<?xml version="1.0"?>
<robot xmlns:xacro="http://www.ros.org/wiki/xacro" name="norma">

  <material name="blue">
    <color rgba="0 0 0.8 1"/>
  </material>

  <material name="gray">
    <color rgba="0.8 0.8 0.8 1"/>
  </material>

  <xacro:property name="base_size" value="1.0 1.2 1.5" />
  <link name="base_link">
    <visual>
      <geometry>
        <box size="${base_size}"/>
      </geometry>
      <material name="blue"/>
    </visual>

    <collision>
      <geometry>
        <box size="${base_size}"/>
      </geometry>
    </collision>
  </link>

  <xacro:property name="wheel_radious" value="0.2" />
  <xacro:property name="wheel_length" value="0.1" />
  <link name="left_wheel">
    <visual>
      <geometry>
        <cylinder length="0.1" radius="0.20"/>
      </geometry>
      <origin rpy="0 1.57075 0"/>
      <material name="gray"/>
    </visual>
  </link>


  <joint name="base_to_left_wheel" type="continuous">
    <parent link="base_link"/>
    <child link="left_wheel"/>
    <origin xyz="0.55 0 -0.75"/>
    <axis xyz="1 0 0"/>
  </joint>

</robot>

