<?xml version="1.0"?>
<robot xmlns:xacro="http://www.ros.org/wiki/xacro" name="norma">

  <material name="blue">
    <color rgba="0 0 0.8 1"/>
  </material>

  <material name="gray">
    <color rgba="0.8 0.8 0.8 1"/>
  </material>

  <xacro:property name="base_mass" value="25" />
  <xacro:property name="base_size_x" value="1.0" />
  <xacro:property name="base_size_y" value="1.2" />
  <xacro:property name="base_size_z" value="1.5" />
  <xacro:property name="base_size" value="${base_size_x} ${base_size_y} ${base_size_z}" />
  <link name="dummy">
    <visual>
      <geometry>
        <box size="${base_size}"/>
      </geometry>
      <material name="blue"/>
    </visual>

    <collision>
      <geometry>
        <box size="${base_size}"/>
      </geometry>
    </collision>
    <inertial>
      <mass value="${base_mass}"/>
      <inertia ixx="${1/12*base_mass*(base_size_z*base_size_z+base_size_y*base_size_y)}" ixy="0.0" ixz="0.0" iyy="${1/12*base_mass*(base_size_x*base_size_x+base_size_z*base_size_z)}" iyz="0.0" izz="${1/12*base_mass*(base_size_x*base_size_x+base_size_y*base_size_y)}"/>
    </inertial>
  </link>
  <link name="base_link"></link>
  <joint name="dummy_joint" type="fixed">
     <parent link="base_link"/>
     <child link="dummy"/>
   </joint>

  <xacro:property name="wheel_radious" value="0.2" />
  <xacro:property name="wheel_length" value="0.1" />
  <xacro:property name="wheel_mass" value="1" />
  <xacro:macro name="wheel" params="wheel_name reflect">
    <link name="${wheel_name}_wheel">
      <visual>
        <geometry>
          <cylinder length="${wheel_length}" radius="${wheel_radious}"/>
        </geometry>
        <origin rpy="0 1.57075 0"/>
        <material name="gray"/>
      </visual>

      <collision>
        <geometry>
          <cylinder length="${wheel_length}" radius="${wheel_radious}"/>
        </geometry>
        <origin rpy="0 1.57075 0"/>
      </collision>

      <inertial>
        <mass value="${wheel_mass}"/>
        <inertia ixx="${1/12*wheel_mass*(3*wheel_radious*wheel_radious+wheel_length*wheel_length)}" ixy="0.0" ixz="0.0" iyy="${1/12*wheel_mass*(3*wheel_radious*wheel_radious+wheel_length*wheel_length)}" iyz="0.0" izz="${1/2*wheel_mass*wheel_radious*wheel_radious}"/>
      </inertial>
    </link>

    <joint name="base_to_${wheel_name}_wheel" type="continuous">
      <parent link="base_link"/>
      <child link="${wheel_name}_wheel"/>
      <origin xyz="${reflect*(base_size_x+wheel_length)/2} 0 ${-base_size_z/2+wheel_radious-0.01}"/>
      <axis xyz="1 0 0"/>
    </joint>
    <transmission name="${wheel_name}_wheel_trans">
      <type>transmission_interface/SimpleTransmission</type>
      <actuator name="${wheel_name}_wheel_motor">
        <mechanicalReduction>1</mechanicalReduction>
      </actuator>
      <joint name="base_to_${wheel_name}_wheel">
        <hardwareInterface>hardware_interface/VelocityJointInterface</hardwareInterface>
      </joint>
    </transmission>
  </xacro:macro>

  <xacro:wheel wheel_name="left" reflect="-1"/>
  <xacro:wheel wheel_name="right" reflect="1"/>

  <xacro:macro name="sensor_hokuyo" params="parent">
    <link name="sensor_laser">
      <collision>
        <origin xyz="0.05 0 0" rpy="0 0 0"/>
        <geometry>
          <cylinder radius="0.05" length="0.1"/>
        </geometry>
      </collision>
      <visual>
        <origin xyz="0.05 0 0" rpy="0 0 0"/>
        <geometry>
          <cylinder radius="0.05" length="0.1"/>
        </geometry>
      </visual>
      <inertial>
        <mass value="1e-5" />
        <inertia ixx="1e-6" ixy="0" ixz="0" iyy="1e-6" iyz="0" izz="1e-6" />
      </inertial>
    </link>
    <joint name="hokuyo_joint" type="fixed">
      <axis xyz="0 0 1" />
      <origin xyz="0 ${base_size_y/2+1} 0.05" rpy="0 0 1.570796"/>
      <parent link="${parent}"/>
      <child link="sensor_laser"/>
    </joint>
  </xacro:macro>

  <gazebo reference="sensor_laser">
    <sensor type="ray" name="head_hokuyo_sensor">
      <pose>0 0 0 0 0 0</pose>
      <visualize>false</visualize>
      <update_rate>20</update_rate>
      <ray>
        <scan>
          <horizontal>
            <samples>720</samples>
            <resolution>1</resolution>
            <min_angle>-1.570796</min_angle>
            <max_angle>1.570796</max_angle>
          </horizontal>
        </scan>
        <range>
          <min>0.10</min>
          <max>10.0</max>
          <resolution>0.01</resolution>
        </range>
        <noise>
          <type>gaussian</type>
          <mean>0.0</mean>
          <stddev>0.01</stddev>
        </noise>
      </ray>
      <plugin name="gazebo_ros_head_hokuyo_controller" filename="libgazebo_ros_laser.so">
        <topicName>/laser/scan</topicName>
        <frameName>sensor_laser</frameName>
      </plugin>
    </sensor>
  </gazebo>

  <xacro:sensor_hokuyo parent="base_link"/>

  <gazebo>
    <plugin name="gazebo_ros_control" filename="libgazebo_ros_control.so">
      <robotNamespace>/</robotNamespace>
    </plugin>
  </gazebo>
</robot>

